Workbook

Sheet Responsables empresas
A1: PÁGINA PARA DEFINIR QUE PERSONAS AGREGAN Y EDITAN LOS DATOS POR EMPRESA Y QUE PERSONAS REVISAN ESTOS DATOS
A2: *POR FAVOR SOLO LAS PERSONAS CON BUEN DOMINIO DE EXCEL TOMEN EL ROL DE EDITORES (ASI EVITAREMOS MUCHOS ERRORES)
B5: EMPRESA | C5: Empresa | D5: ¿Quién EDITA LOS DATOS DE LA EMPRESA? | E5: ESTADO DE LLENADO? Indicar Trimetre y Año de datos (ejemplo: Q4-2025) | F5: Contacto EDITOR | G5: Comentario EDITOR | H5: ¿Quién REVISA LOS DATOS DE LA EMPRESA? | I5: Contacto EDITOR | J5: Comentario Revisor
A6: TOMAR ESTA HOJA COMO REFERENCIA PARA LLENAR DATOS | B6: EMBOTELLADORA | C6: ANDINA A | D6: Victor Araya | E6: Q4-2025 | F6: 952254143
B7: EMBOTELLADORA | C7: ANDINA B | D7: Victor Araya | E7: Q4-2025
B8: ELÉCTRICAS | C8: COLBUN | D8: Victor Araya | E8: Q4-2025
B9: BANCO | C9: BANCO CHILE | D9: Van Olivares | E9: Q4-2025 | F9: volivaresh@outlook.com | G9: Listo
B10: ELÉCTRICAS | C10: PEHUENCHE | D10: Victor Jofré | E10: NO COMPLETADO
B11: EMBOTELLADORA | C11: EMBONOR B | D11: Victor Jofré | E11: Q4-2025
B12: EMBOTELLADORA | C12: EMBONOR A | D12: Victor Jofré | E12: NO COMPLETADO
B13: AFP | C13: HABITAT | E13: NO COMPLETADO
B14: GAS | C14: LIPIGAS | E14: NO COMPLETADO
B15: AFP | C15: AAISA | E15: NO COMPLETADO
B16: CONCESIÓN | C16: ZOFRI | E16: NO COMPLETADO
B17: HOLDING | C17: QUIÑENCO | D17: Manuel González | E17: Q4-2025 | F17: (+56)941389809
B18: INMOBILIARIO | C18: CENCOMALLS | D18: Manuel González | E18: Q4-2025
B19: ELÉCTRICAS | C19: ENELGXCH | E19: NO COMPLETADO
B20: AFP | C20: PROVIDA | D20: Alvaro De la Quintana | E20: Q4-2025
B21: AFP | C21: PLANVITAL | D21: Alvaro De la Quintana | E21: Q4-2024
B22: AFP | C22: CUPRUM | D22: Alvaro De la Quintana | E22: Q4-2025
B23: AFP | C23: AFPCAPITAL | D23: Alvaro De la Quintana | E23: Q4-2024
B24: ELÉCTRICAS | C24: CGE | D24: Manuel González | E24: Q4-2025
B25: ELÉCTRICAS | C25: EDELMAG | E25: NO COMPLETADO
B26: GAS | C26: NTGCLGAS | E26: NO COMPLETADO
B27: GAS | C27: GASCO | D27: Alvaro De la Quintana | E27: Q4-2025
B28: EMBOTELLADORA | C28: CCU | D28: Jean Herrera | E28: Q4-2025
B29: ELÉCTRICAS | C29: ENELCHILE | D29: Jean Herrera | E29: Q4-2024
B30: BANCO | C30: SANTANDER | D30: Manuel González | E30: Q4-2025 | F30: (+56)941389809
B31: SUPERMERCADOS | C31: SMU | D31: Manuel González | E31: Q4-2025 | F31: (+56)941389809
B32: INMOBILIARIO | C32: PARAUCO | D32: Alvaro De la Quintana | E32: Q4-2025
B33: INMOBILIARIO | C33: MALLPLAZA | D33: Alvaro De la Quintana | E33: Q4-2025
B34: FERTILIZANTES | C34: SOQUICOM | D34: Gian Carlo Giuliano | E34: Q1-2025 | F34: (+56)998724806
B35: ELÉCTRICAS | C35: TRICAHUE | E35: NO COMPLETADO | F35: jpg139@gmail.com
B36: FINANCIERA | C36: NUAM | D36: Edo Otero | E36: Q4-2025 | F36: eoterovtmt@gmail.com
B37: HOLDING | C37: ILC | E37: NO COMPLETADO
C38: CFINRENTAS | D38: Diego Muñoz C | E38: Por crear
D46: {=_xlfn.UNIQUE(D7:D38)} -> Victor Araya
D47: Van Olivares
D48: Victor Jofré
D49: 0
...

Sheet Cuidados a tener en la planilla
B2: POR FAVOR TOMAR EN CUENTA ESTAS INDICACIONES ANTES DE EDITAR LAS EMPRESAS
B4: Por favor solo las personas que se sientan bien capacitadas en Excel tomen el rol de "editores" de las hojas. Las demás solo contribuyan revisando, pero no editando. En conjunto haremos que esto funcione.
B5: Se deben llenar los dividendos "año calendario" y los dividendos "año utilidad" según se indica en hoja "Como llenar dividendos". Esto es LA PARTE PRINCIPAL Y MÁS DIFÍCIL.
B6: En toda empresa se debe agregar el concepto "PRECIO" en alguna fila de la columna B asociada al año 2017 (y no en otro año). Este precio debe apuntar al precio al cual cotiza la empresa. CLAVE QUE FUNCIONE
B7: No cambiar el nombre de las hojas a las empresas que ya están listas en Power BI. Si la hoja se llama Andina A, dejar tal como está.
B8: La columna A de todas las empresas debe estar vacía (debe existir, pero en blanco sin datos)
B9: Cuando agregues datos de una nueva empresa que no esté en Power BI, debes ir a hoja "Empresas Power BI" y llenar sus datos (usa el mismo nombre de hoja de empresa). LUEGO AVÍSAME PARA INCLUIRLA
B10: La columna B (únicamente) debe tener los conceptos a usar (activos corrientes, Cuentas por cobrar, etc). Deben tener exactamente los mismos nombres en todas las empresas.
B11: Tomar ANDINA-A como referencia de los conceptos. Es decir, estos son los nombres que se usarán en Power BI y que deben ser iguales en todas las empresas donde aplique.
B12: No importa si un mismo concepto en una empresa se encuentra fila 5 y en otra se encuentra en fila 20 (solo importa que estén en columna B y que tengan EXACTAMENTE el mismo nombre)
B13: Power BI solo está usando los conceptos que ven en ese reporte. Más adelante podremos incluir más cosas que crean relevantes.
B14: Power BI distingue entre mayúsculas, minúsculas, espacios, saltos de líneas, etc. Los nombres a usar en todas las empresas deben ser EXACTAMENTE iguales y UBICADOS EN LA MISMA COLUMNA B.
... B23: Cualquier duda la pueden escribir aquí mismo.

Sheet Actualización de POWER BI
B1: Actualización Power BI
B3: Enlace a reporte (público): | C3: https://app.powerbi.com/view?r=eyJrIjoiZDNmYTQ1YjYtZGJmOS00MWUwLTg1Y2QtNGMyNTZkMjEyNTkxIiwidCI6IjYxZWJjMzI1LWFlNTAtNDhmZC1iOTdmLTk5ZDI3N2RmMjg3NCIsImMiOjR9
B5: Frecuencia de actualización (AM):
B6: 8:30, 9, 9:30, 10, 10:30, 11, 11:30 y 12 hrs todos los días (consideren un delay de 30 minutos, aunque en general es menos)
B7: El reporte se actualizará solo en estos horarios y tomará lo que vea en este Excel en ese momento.
B9: Abrir Excel 1 vez por día al menos para reflejar cambio de precios (solo basta 1 vez, ejecutado por cualquier persona).
B10: Dado que los precios de las acciones solo cambian cuando se abre el Excel, es necesario por ahora que cualquier persona abra el Excel en la mañana.
B11: Cuando tenga tiempo pienso mejorar esto, de forma que el archivo se abra y se cierre solo.
B12: Debe haber algo mejor, así que por favor cualquier idea de mejora vamos compartiendo!

Sheet Como llenar dividendos
B2: En todas las hojas debemos llenar 2 tipos de dividendos, GRUPO 1 y GRUPO 2 (ver ANDINA-A como referencia) | D2: EJEMPLO ANDINA-A CON DATOS EN FOTO (MISMOS DIVIDENDOS, PERO ASOCIADOS A AÑOS DISTINTOS). SE LLENAN AMBOS TIPOS.
B3: GRUPO 1: Los dividendos se deben dejar en la columna del año en el cual se reparten (año calendario). Es el más simple de llenar.
B4: GRUPO 2: Los dividendos se deben dejar en la columna del año al cual corresponde realmente la utilidad (año fiscal). Es el más difícil de llenar.
O6: Año 2025
B7: LOS NOMBRES QUE SE DEBEN USAR EN CADA HOJA DE EMPRESA SON: | F7: Utilidad 2024
O8: Año 2024
B9: Dividendos calendario
B10: Dividendos sin eventual Calendario | F10: Utilidad 2023
B11: Definitivo año calendario
B12: Provisorio calendario
B13: Adicional calendario
B14: Eventual calendario | D14: Pueden revisar los fórmulas para que vean como se van asociando los dividendos al año correcto, según año calendario o según año de utilidad (fiscal)
B15: Dividendos | E15: 2023 | F15: 2024 | G15: 2025
B16: Dividendos sin eventual | D16: Dividendos calendario | E16: =SUM(E18:E21) -> 0 | F16: =SUM(F18:F21) -> 158 | G16: =SUM(G18:G21) -> 141
B17: Definitivo | D17: Dividendos sin eventual Calendario | E17: =SUM(E18:E20) -> 0 | F17: =SUM(F18:F20) -> 158 | G17: =SUM(G18:G20) -> 141
B18: Provisorio | D18: Definitivo año calendario | F18: =30+32+32 -> 94
B19: Adicional | D19: Provisorio calendario | F19: =32+32 -> 64 | G19: 141
B20: Eventual | D20: Adicional calendario
D21: Eventual calendario
B22: SE DEBEN USAR EXACTAMENTE ESTOS NOMBRES | D22: Dividendos | E22: =SUM(E24:E27) -> 94 | F22: =SUM(F24:F27) -> 205 | G22: =SUM(G24:G27) -> 0
B23: SI EN ALGUNA HOJA NO VEN ESTOS NOMBRES, SE DEBEN CREAR INSERTANDO FILAS | D23: Dividendos sin eventual | E23: =SUM(E24:E26) -> 94 | F23: =SUM(F24:F26) -> 205 | G23: =SUM(G24:G26) -> 0
B24: NO IMPORTA LA POSICIÓN DE LA FILA (PUEDEN ESTAR EN LAS ÚLTIMAS FILAS O ANTES, DA IGUAL) | D24: Definitivo | E24: =30+32+32 -> 94
B25: SI IMPORTA LA POSICIÓN DE LA COLUMNA (TODOS LOS CONCEPTOS VAN EN LA COLUMNA B) | D25: Provisorio | F25: =141+32+32 -> 205
B26: LOS COLORES NO IMPORTAN, SON SOLO PARA RESALTAR LA DIFERENCIA DE DIVIDENDO EN ESTA PÁGINA | D26: Adicional
D27: Eventual

Sheet Empresas Power BI
B1: NO MODIFICAR NOMBRE DE TABLA NI NOMBRE DE COLUMNAS
B2: AGREGAR FILAS CUANDO EXISTA UNA EMPRESA NUEVA QUE NO ESTÉ EN EL POWER BI
B4: Empresas | C4: Industria | D4: TIPO EMPPRESA
B5: CHILE | C5: BANCOS | D5: DGI
B6: COLBÚN | C6: ELÉCTRICAS | D6: DGI
B7: LIPIGAS | C7: GAS | D7: DGI
B8: CENCOMALLS | C8: INMOBILIARIO | D8: DGI
B9: ANDINA A | C9: EMBOTELLADORA | D9: DGI
B10: ANDINA B | C10: EMBOTELLADORA | D10: DGI
B11: EMBONOR A | C11: EMBOTELLADORA | D11: DGI
B12: EMBONOR B | C12: EMBOTELLADORA | D12: DGI
B13: QUINENCO | C13: HOLDING | D13: DGI
B14: ENELGXCH | C14: ELÉCTRICAS | D14: DGI
B15: CGE | C15: ELÉCTRICAS | D15: DGI
... B28: ZOFRI | C28: CONCESIÓN | D28: VACA LECHERA
B29: PROVIDA | C29: AFP | D29: VACA LECHERA | F29: No están completos estos datos TRICAHUE. Faltan dividendos "Utilidad" y no está en hoja Responsables
B30: PLANVITAL | C30: AFP | D30: VACA LECHERA
B31: CUPRUM | C31: AFP | D31: VACA LECHERA
B32: AFPCAPITAL | C32: AFP | D32: VACA LECHERA
B33: GASCO | C33: GAS | D33: VACA LECHERA
B34: TRICAHUE | C34: ELÉCTRICAS | D34: VACA LECHERA
B35: SOQUICOM | C35: FERTILIZANTES | D35: VACA LECHERA

Sheet EMPRESAS SELECCIONADAS (2)
B1: EMPRESA | C1: PEHUENCHE
B3: ¿BUENA EMPRESA?
B5: BALANCE
B6: KPI | C6: Criterio | D6: 2022 | E6: 2023 | F6: 2024 | G6: SEMAFORO
A7: =AVERAGE(D7:F7) -> 46092274000 | B7: Capital de Trabajo | C7: Positivo | D7: =IFERROR(PEHUENCHE!H29,"") -> 56284731000 | E7: =IFERROR(PEHUENCHE!I29,"") -> 40793989000 | F7: =IFERROR(PEHUENCHE!J29,"") -> 41198102000 | G7: =IF(SLOPE(D7:F7, $D$6:$F$6)>0, "Creciente", "Decreciente") -> Decreciente
A8: =AVERAGE(D8:F8) -> 1.7291904 | B8: Razón corriente | C8: Bueno: 1,5-2 | D8: =IFERROR(PEHUENCHE!H30,"") -> 1.5780628 | E8: =IFERROR(PEHUENCHE!I30,"") -> 1.809672 | F8: =IFERROR(PEHUENCHE!J30,"") -> 1.7998364 | G8: =IF(A8<1,"🔴",IF(AND(A8>=1.5,A8<=2), "🟢","🟡")) -> 🟢
A9: =AVERAGE(D9:F9) -> 1.7237744 | B9: Razón acida | C9: Bueno: 1-1,5 | D9: =IFERROR(PEHUENCHE!H31,"") -> 1.5754473 | E9: =IFERROR(PEHUENCHE!I31,"") -> 1.8015064 | F9: =IFERROR(PEHUENCHE!J31,"") -> 1.7943694 | G9: =IF(A9<1,"🔴",IF(AND(A9>=1,A9<=1.5), "🟢","🟡")) -> 🟡
A10: =AVERAGE(D10:F10) -> 0.37667865 | B10: Razón de endeudamiento | C10: Max 50% | D10: =IFERROR(PEHUENCHE!H32,"") -> 0.43705173 | E10: =IFERROR(PEHUENCHE!I32,"") -> 0.3515346 | F10: =IFERROR(PEHUENCHE!J32,"") -> 0.34144963 | G10: =IF(A10<40%,"🔴",IF(AND(A10>=40%,A10<=50%), "🟢","🟡")) -> 🔴
B12: EERR
B13: KPI | C13: Criterio | D13: 2022 | E13: 2023 | F13: 2024 | G13: SEMAFORO
B14: EBIT | C14: Creciente | D14: =IFERROR(PEHUENCHE!H35,"") -> 248835472000 | E14: =IFERROR(PEHUENCHE!I35,"") -> 194705044000 | F14: =IFERROR(PEHUENCHE!J35,"") -> 217595776000 | G14: =IF(SLOPE(D14:F14, $D$13:$F$13)>0, "Creciente", "Decreciente") -> Decreciente
B15: %MARGEN EBITDA | C15: Creciente | D15: =IFERROR(PEHUENCHE!H36,"") -> 0.91335228 | E15: =IFERROR(PEHUENCHE!I36,"") -> 0.89430275 | F15: =IFERROR(PEHUENCHE!J36,"") -> 0.87355741 | G15: =IF(SLOPE(D15:F15, $D$13:$F$13)>0, "Creciente", "Decreciente") -> Decreciente
B16: EPS | C16: Creciente | D16: =IFERROR(PEHUENCHE!H39,"") -> 305.1 | E16: =IFERROR(PEHUENCHE!I39,"") -> 241.02 | F16: =IFERROR(PEHUENCHE!J39,"") -> 264.12 | G16: =IF(SLOPE(D16:F16, $D$13:$F$13)>0, "Creciente", "Decreciente") -> Decreciente
B17: ROE | C17: Constante o > 15% | D17: =IFERROR(PEHUENCHE!H40,"") -> 1.0702614 | E17: =IFERROR(PEHUENCHE!I40,"") -> 0.92362252 | F17: =IFERROR(PEHUENCHE!J40,"") -> 0.97760982 | G17: =IF(AVERAGE(D17:F17)<15%,"🔴",IF(AND(AVERAGE(D17:F17)>=15%,AVERAGE(D17:F17)<=100%), "🟢","🟡")) -> 🟢
B19: FCF
B20: KPI | C20: Criterio | D20: 2022 | E20: 2023 | F20: 2024 | G20: SEMAFORO
B21: FCF Simplificado | C21: Creciente | D21: ='ANDINA A'!H43 -> 210750245000 | E21: ='ANDINA A'!I43 -> 174122738000 | F21: ='ANDINA A'!J43 -> 65700300000 | G21: =IF(SLOPE(D21:F21, $D$20:$F$20)>0, "Creciente", "Decreciente") -> Decreciente
B24: ¿BUEN PRECIO?
B26: TIPO EMPRESA | C26: DGI
B28: KPI | C28: 2022 | D28: 2023 | E28: 2024 | F28: PROMEDIO
B29: Dividendos | C29: =IFERROR(PEHUENCHE!H44,"") -> 203.678 | D29: =IFERROR(PEHUENCHE!I44,"") -> 311.995 | E29: =IFERROR(PEHUENCHE!J44,"") -> 251.33 | F29: =AVERAGE(C29:E29) -> 255.66767
B30: PAY OUT | C30: =IFERROR(PEHUENCHE!H55,"") -> 0.99998361 | D30: =IFERROR(PEHUENCHE!I55,"") -> 1.0000041 | E30: =IFERROR(PEHUENCHE!J55,"") -> 1.0000151 | F30: =AVERAGE(C30:E30) -> 1.000001
B31: ROE | C31: =IFERROR(PEHUENCHE!H40,"") -> 1.0702614 | D31: =IFERROR(PEHUENCHE!I40,"") -> 0.92362252 | E31: =IFERROR(PEHUENCHE!J40,"") -> 0.97760982 | F31: =AVERAGE(C31:E31) -> 0.99049791
B33: VALORIZACION POR DIVIDENDOS | E33: VALORIZACION "ME SIRVE"
B35: Dividendos Promedio 3 Ultimado años | C35: =+F29 -> 255.66767 | E35: Dividendos Promedio 3 Ultimado años | F35: =+F29 -> 255.66767
B36: PAY OUT Promedio 3 Ultimado años | C36: =+F30 -> 1.000001 | E36: PRECIO ACTUAL ACCION AL 22/FEB | F36: =C44 -> 2800
B37: % RETENCION | C37: =100%-C36 -> -9.6853167e-07 | E37: Rentabilidad por Dividendo | F37: =F35/F36 -> 0.091309881
B38: ROE Promedio 3 Ultimado años | C38: =+F31 -> 0.99049791
B39: G | C39: =IF((C38*C37)<0,0,(C38*C37)) -> 0
B40: TASA EXIGIDA % | C40: 0.1
B42: PRECIO MAXIMO | C42: =(C35*(1+C39)) /C40 -> 2556.6767
B44: PRECIO ACTUAL ACCION AL 22/FEB | C44: 2800 | D44: =IF(C44>C42,"Precio muy Alto","Compra Ahora") -> Precio muy Alto

Sheet EMPRESAS SELECCIONADAS
B1: EMPRESA | C1: ANDINA - A
B3: ¿BUENA EMPRESA?
B5: BALANCE
B6: KPI | C6: Criterio | D6: 2022 | E6: 2023 | F6: 2024 | G6: SEMAFORO
B7: Capital de Trabajo | C7: Positivo | D7: =+'ANDINA A'!H29 -> 212484258000 | E7: =+'ANDINA A'!I29 -> 288899731000 | F7: =+'ANDINA A'!J29 -> 107051746000
B8: Razón corriente | C8: Bueno: 1,5-2 | D8: =+'ANDINA A'!H30 -> 1.2238455 | E8: =+'ANDINA A'!I30 -> 1.4169602 | F8: =+'ANDINA A'!J30 -> 1.1181399
B9: Razón acida | C9: Bueno: 1-1,5 | D9: ='ANDINA A'!H31 -> 0.96481162 | E9: ='ANDINA A'!I31 -> 1.0806017 | F9: ='ANDINA A'!J31 -> 0.78709878
B10: Razón de endeudamiento | C10: Max 50% | D10: ='ANDINA A'!H32 -> 0.70657904 | E10: ='ANDINA A'!I32 -> 0.68475823 | F10: ='ANDINA A'!J32 -> 0.69177609
B12: EERR
B13: KPI | C13: Criterio | D13: 2022 | E13: 2023 | F13: 2024 | G13: SEMAFORO
B14: EBITDA | C14: Creciente | D14: ='ANDINA A'!H36 -> 321771470000 | E14: ='ANDINA A'!I36 -> 316296892000 | F14: ='ANDINA A'!J36 -> 411911208000
B15: %MARGEN EBITDA | C15: Creciente | D15: =+'ANDINA A'!H37 -> 0.12110884 | E15: =+'ANDINA A'!I37 -> 0.12079606 | F15: =+'ANDINA A'!J37 -> 0.12775479
B16: EPS | C16: Creciente | D16: ='ANDINA A'!H40 -> 126.27 | E16: ='ANDINA A'!I40 -> 172.49 | F16: ='ANDINA A'!J40 -> 234.09
B17: ROE | C17: Constante o > 15% | D17: ='ANDINA A'!H41 -> 0.15019873 | E17: ='ANDINA A'!I41 -> 0.196901 | F17: ='ANDINA A'!J41 -> 0.24031331
B19: FCF
B20: KPI | C20: Criterio | D20: 2022 | E20: 2023 | F20: 2024 | G20: SEMAFORO
B21: FCF Simplificado | C21: Creciente | D21: ='ANDINA A'!H43 -> 210750245000 | E21: ='ANDINA A'!I43 -> 174122738000 | F21: ='ANDINA A'!J43 -> 65700300000
B24: ¿BUEN PRECIO?
B26: TIPO EMPRESA | C26: DGI
B28: KPI | C28: 2022 | D28: 2023 | E28: 2024 | F28: PROMEDIO
B29: Dividendos | C29: ='ANDINA A'!H44 -> 276 | D29: ='ANDINA A'!I44 -> 166 | E29: ='ANDINA A'!J44 -> 158 | F29: =AVERAGE(C29:E29) -> 200 | G29: ? incluye eventuales??
B30: PAY OUT | C30: ='ANDINA A'!H56 -> 0.91866635 | D30: ='ANDINA A'!I56 -> 0.8812105 | E30: ='ANDINA A'!J56 -> 0.87573156 | F30: =AVERAGE(C30:E30) -> 0.89186947
B31: ROE | C31: ='ANDINA A'!H41 -> 0.15019873 | D31: ='ANDINA A'!I41 -> 0.196901 | E31: ='ANDINA A'!J41 -> 0.24031331 | F31: =AVERAGE(C31:E31) -> 0.19580435
B33: VALORIZACION POR DIVIDENDOS | E33: VALORIZACION "ME SIRVE"
B35: Dividendos Promedio 3 Ultimado años | C35: =+F29 -> 200 | E35: Dividendos Promedio 3 Ultimado años | F35: =+F29 -> 200
B36: PAY OUT Promedio 3 Ultimado años | C36: =+F30 -> 0.89186947 | E36: PRECIO ACTUAL ACCION AL 22/FEB | F36: 2406.8
B37: % RETENCION | C37: =100%-C36 -> 0.10813053 | E37: Rentabilidad por Dividendo | F37: =F35/F36 -> 0.083097889
B38: ROE Promedio 3 Ultimado años | C38: =+F31 -> 0.19580435
B39: G | C39: =IF((C38*C37)<0,0,(C38*C37)) -> 0.021172428
B40: TASA EXIGIDA % | C40: 0.07
B42: PRECIO MAXIMO | C42: =(C35*(1+C39)) /C40 -> 2917.6355
B44: PRECIO ACTUAL ACCION AL 22/FEB | C44: 2406.8

Sheet INDICE
H1: =+CGE!C42 -> 0.013524965
F2: MANUAL | H2: =+FOSFOROS!C42 -> 0.02082139 | Q2: DIVIDENDOS SIN ADIC/EVENTUALES | V2: DIVIDENDOS TOTALES
B3: LISTADO EMPRESAS DIVIDENDERAS | H3: =+ENELAM!C45 -> 0.037970316 | Q3: RENT ESPERADA | R3: 0.07 | V3: RENT ESPERADA | W3: 0.08
B4: CANTIDAD | C4: EMPRESA | D4: INDUSTRIA | F4: PRECIO DE CIERRE | H4: =+GASCO!C42 -> 0.042946098 | K4: G | M4: PAYOUT | O4: DY | Q4: PRECIO MAX A CONSIDERAR | T4: Ret Est Precio Cierre | V4: PRECIO MAX A CONSIDERAR | Y4: Ret Est Precio Cierre
B5: 22 | C5: ANDINA-A | D5: EMBOTELLADORA | F5: =+'ANDINA A'!B3 -> 3475 | H5: =+MANQUEHUE!C42 -> 0.052257279 | K5: =+'ANDINA A'!C61 -> 0.02519583 | M5: =+'ANDINA A'!C57 -> 0.89186947 | O5: =+'ANDINA A'!C57 -> 0.89186947 | Q5: =+'ANDINA A'!D3/INDICE!$R$3 -> 2238.0952 | S5: =IF(F5<Q5,"considerar","esperar") -> esperar | T5: =+'ANDINA A'!D3/INDICE!F5 -> 0.045083933 | V5: =+'ANDINA A'!E3/INDICE!$W$3 -> 2500 | X5: =IF(F5<V5,"considerar","esperar") -> esperar | Y5: =+'ANDINA A'!E3/INDICE!F5 -> 0.057553957 | AA5: =F9/R3 -> 179500
B6: 2 | C6: PROVIDA | D6: AFP | F6: =+PROVIDA!B3 -> 5000 | H6: =+NTGCLGAS!C44 -> 0.065494433 | K6: =+PROVIDA!C64 -> 0.0078442042 | M6: =+PROVIDA!C60 -> 0.93285353 | O6: =+PROVIDA!C62 -> 0.13339977 | Q6: =+PROVIDA!D3/INDICE!$R$3 -> 4916.6667 | S6: =IF(F6<Q6,"considerar","esperar") -> esperar | T6: =+PROVIDA!D3/INDICE!F6 -> 0.068833333 | V6: =+PROVIDA!E3/INDICE!$W$3 -> 4927.0833 | X6: =IF(F6<V6,"considerar","esperar") -> esperar | Y6: =+PROVIDA!E3/INDICE!F6 -> 0.078833333
B7: 15 | C7: COLBUN | D7: ELÉCTRICAS | F7: =+COLBÚN!B3 -> 127.23 | H7: =+SONDA!C42 -> 0.068190047 | K7: =+COLBÚN!C63 -> 0.060522633 | M7: =+COLBÚN!C59 -> 0.59920595 | O7: =+COLBÚN!C61 -> 0.33310742 | Q7: =+COLBÚN!D3/INDICE!$R$3 -> 139.88571 | S7: =IF(F7<Q7,"considerar","esperar") -> considerar | T7: =+COLBÚN!D3/INDICE!F7 -> 0.07696298 | V7: =+COLBÚN!E3/INDICE!$W$3 -> 122.4 | X7: =IF(F7<V7,"considerar","esperar") -> esperar | Y7: =+COLBÚN!E3/INDICE!F7 -> 0.07696298
B8: 3 | C8: PLANVITAL | D8: AFP | F8: =+PLANVITAL!B3 -> 282 | H8: =+'SALFACORP (TIKR)'!C42 -> 0.068789745 | K8: =PLANVITAL!C65 -> 0.2448118 | M8: =+PLANVITAL!C61 -> 0.47082548 | O8: =+PLANVITAL!C63 -> 0.25899326 | Q8: =+PLANVITAL!D3/INDICE!$R$3 -> 137.08095 | S8: =IF(F8<Q8,"considerar","esperar") -> esperar | T8: =+PLANVITAL!D3/INDICE!F7 -> 0.075419843 | V8: =+PLANVITAL!E3/INDICE!$W$3 -> 163.19583 | X8: =IF(F8<V8,"considerar","esperar") -> esperar | Y8: =+PLANVITAL!E3/INDICE!F8 -> 0.04629669
B9: 41 | C9: MINERA VALPARAISO | D9: HOLDING | F9: =+MINERA!B3 -> 12565 | H9: =+IAM!C42 -> 0.073837133 | K9: =+MINERA!C59 -> 0.038926328 | M9: =+MINERA!C55 -> 0.64848843 | O9: =+MINERA!C57 -> 0.24299225 | Q9: =MINERA!D3/INDICE!$R$3 -> 22152.081 | S9: =IF(F9<Q9,"considerar","esperar") -> considerar | T9: =MINERA!D3/INDICE!F9 -> 0.12340992 | V9: =MINERA!E3/INDICE!$W$3 -> 37987.238 | X9: =IF(F9<V9,"considerar","esperar") -> considerar | Y9: =MINERA!E3/INDICE!F9 -> 0.24186064
B10: 4 | C10: CUPRUM | D10: AFP | F10: =+CUPRUM!B3 -> 136.87 | H10: =+'EISA (TIKR)'!C42 -> 0.077143735 | K10: =+CUPRUM!C64 -> 0.029484641 | M10: =+CUPRUM!C60 -> 0.81353543 | O10: =+CUPRUM!C62 -> 0.18028205 | Q10: =+CUPRUM!D3/INDICE!$R$3 -> 72.642857 | S10: =IF(F10<Q10,"considerar","esperar") -> esperar | T10: =+CUPRUM!D3/INDICE!F10 -> 0.037152042 | V10: =+CUPRUM!E3/INDICE!$W$3 -> 63.5625 | X10: =IF(F10<V10,"considerar","esperar") -> esperar | Y10: =+CUPRUM!E3/INDICE!F10 -> 0.037152042
B11: 1 | C11: HABITAT | D11: AFP | F11: =+HABITAT!B3 -> 1412 | H11: =+ELECMETAL!C42 -> 0.082637849 | K11: =+HABITAT!C65 -> 0.11925541 | M11: =+HABITAT!C61 -> 0.87767228 | O11: =+HABITAT!C63 -> 0.17112404 | Q11: =+HABITAT!D3/INDICE!$R$3 -> 1657.1429 | S11: =IF(F11<Q11,"considerar","esperar") -> considerar | T11: =+HABITAT!D3/INDICE!F11 -> 0.082152975 | V11: =+HABITAT!E3/INDICE!$W$3 -> 1450 | X11: =IF(F11<V11,"considerar","esperar") -> considerar | Y11: =+HABITAT!E3/INDICE!F11 -> 0.082152975
B12: 34 | C12: ENTEL | D12: TELECOMUNICACIONES | F12: =+ENTEL!B3 -> 3756 | H12: =+MOLYMET!C46 -> 0.085536314 | K12: =+ENTEL!C55 -> 0.065281794 | M12: =+ENTEL!C51 -> 0.61392432 | O12: =+ENTEL!C53 -> 0.24783216 | Q12: f | S12: =IF(F12<Q12,"considerar","esperar") -> considerar | T12: =+ENTEL!D3/INDICE!F12 -> 0.089013135 | V12: =+ENTEL!E3/INDICE!$W$3 -> 9054.1667 | X12: =IF(F12<V12,"considerar","esperar") -> considerar | Y12: =+ENTEL!E3/INDICE!F12 -> 0.192847
B13: 13 | C13: PEHUENCHE | D13: ELÉCTRICAS | F13: =+PEHUENCHE!B3 -> 2719.9 | H13: =+CMPC!C46 -> 0.086055536 | K13: =+PEHUENCHE!C60 -> 7.3766171e-06 | M13: =+PEHUENCHE!C56 -> 0.99999203 | O13: =+PEHUENCHE!C58 -> 0.16072435 | Q13: =+PEHUENCHE!D3/INDICE!$R$3 -> 3652.3952 | S13: =IF(F13<Q13,"considerar","esperar") -> considerar | T13: =+PEHUENCHE!D3/INDICE!F13 -> 0.093998922 | V13: =+PEHUENCHE!E3/INDICE!$W$3 -> 2796.0458 | X13: =IF(F13<V13,"considerar","esperar") -> considerar | Y13: =+PEHUENCHE!E3/INDICE!F13 -> 0.082239666
B14: 31 | C14: QUINENCO | D14: HOLDING | F14: =+QUINENCO!B3 -> 4290 | H14: =+'CAP (TIKR)'!C45 -> 0.092288715 | K14: =+QUINENCO!C63 -> 0.11670464 | M14: =+QUINENCO!C59 -> 0.54782351 | O14: =+QUINENCO!C61 -> 0.14017128 | Q14: =+QUINENCO!D3/INDICE!$R$3 -> 4876.3286 | S14: =IF(F14<Q14,"considerar","esperar") -> considerar | T14: =+QUINENCO!D3/INDICE!F14 -> 0.079567133 | V14: =+QUINENCO!E3/INDICE!$W$3 -> 5632.4833 | X14: =IF(F14<V14,"considerar","esperar") -> considerar | Y14: =+QUINENCO!E3/INDICE!F14 -> 0.10503465
B15: 28 | C15: SOQUICOM | D15: FERTILIZANTES | F15: =+SOQUICOM!B3 -> 379 | H15: =+'BESALCO (TIKR)'!C42 -> 0.096985097 | K15: =+SOQUICOM!C79 -> -5.4531897e-06 | M15: =+SOQUICOM!C75 -> 1.0000339 | O15: =+SOQUICOM!C77 -> 0.12801361 | Q15: =+SOQUICOM!D3/INDICE!$R$3 -> 539.89482 | S15: =IF(F15<Q15,"considerar","esperar") -> considerar | T15: =+SOQUICOM!D3/INDICE!F15 -> 0.099716721 | V15: =+SOQUICOM!E3/INDICE!$W$3 -> 472.40796 | X15: =IF(F15<V15,"considerar","esperar") -> considerar | Y15: =+SOQUICOM!E3/INDICE!F15 -> 0.099716721
B16: 14 | C16: TRICAHUE | D16: ELÉCTRICAS | F16: =+TRICAHUE!B3 -> 1480 | H16: =+ANASAC!C41 -> 0.099081064 | K16: =+TRICAHUE!C61 -> 0.13353851 | M16: =+TRICAHUE!C57 -> 0.98374796 | O16: =+TRICAHUE!C59 -> 0.13568046 | Q16: =+TRICAHUE!D3/INDICE!$R$3 -> 1263.2667 | S16: =IF(F16<Q16,"considerar","esperar") -> esperar | T16: =+TRICAHUE!D3/INDICE!F16 -> 0.059749099 | V16: =+TRICAHUE!E3/INDICE!$W$3 -> 1201.6821 | X16: =IF(F16<V16,"considerar","esperar") -> esperar | Y16: =+TRICAHUE!E3/INDICE!F16 -> 0.064955788
B17: 24 | C17: EMBONOR-A | D17: EMBOTELLADORA | F17: ='EMBONOR A'!B3 -> 1401 | H17: =+PROVIDA!C45 -> 0.1113963 | K17: =+'EMBONOR A'!C61 -> 0.090134722 | M17: =+'EMBONOR A'!C57 -> 0.49741452 | O17: =+'EMBONOR A'!C59 -> 0.1203331 | Q17: =+'EMBONOR A'!D3/INDICE!$R$3 -> 717.69771 | S17: =IF(F17<Q17,"considerar","esperar") -> esperar | T17: =+'EMBONOR A'!D3/INDICE!F17 -> 0.035859272 | V17: =+'EMBONOR A'!E3/INDICE!$W$3 -> 1281.7437 | X17: =IF(F17<V17,"considerar","esperar") -> esperar | Y17: =+'EMBONOR A'!E3/INDICE!F17 -> 0.073190217
B18: 36 | C18: SMU | D18: SUPERMERCADOS | F18: =+SMU!B3 -> 130.83 | H18: =+ITAU!C24 -> 0.102933 | K18: =+SMU!C61 -> 0.023285568 | M18: =+SMU!C57 -> 0.70945222 | O18: =+SMU!C59 -> 0.060254467 | Q18: =+SMU!D3/INDICE!$R$3 -> 136.67943 | S18: =IF(F18<Q18,"considerar","esperar") -> considerar | T18: =+SMU!D3/INDICE!F18 -> 0.07312971 | V18: =+SMU!E3/INDICE!$W$3 -> 119.5945 | X18: =IF(F18<V18,"considerar","esperar") -> esperar | Y18: =+SMU!E3/INDICE!F18 -> 0.07312971
B19: 32 | C19: ILC | D19: HOLDING | F19: =+ILC!B3 -> 19999 | H19: =+ENLASA!C46 -> 0.1079164 | K19: =+ILC!C63 -> 0.099300819 | M19: =+ILC!C59 -> 0.35524406 | O19: =+ILC!C61 -> 0.10637525 | Q19: =+ILC!D3/INDICE!$R$3 -> 6333.2033 | S19: =IF(F19<Q19,"considerar","esperar") -> esperar | T19: =+ILC!D3/INDICE!F19 -> 0.02216732 | V19: =+ILC!E3/INDICE!$W$3 -> 5541.5529 | X19: =IF(F19<V19,"considerar","esperar") -> esperar | Y19: =+ILC!E3/INDICE!F19 -> 0.02216732
B20: 35 | C20: OXIQUIM | D20: INDUSTRIAL | F20: 12000 | H20: =+CCU!C42 -> 0.10962882 | K20: =+OXIQUIM!C57 -> 0.11351219 | M20: =+OXIQUIM!C53 -> 0.55696026 | O20: =+OXIQUIM!C55 -> 0.10158454 | Q20: =+OXIQUIM!D3/INDICE!$R$3 -> 8414.2857 | S20: =IF(F20<Q20,"considerar","esperar") -> esperar | T20: =+OXIQUIM!D3/INDICE!F20 -> 0.049083333 | V20: =+OXIQUIM!E3/INDICE!$W$3 -> 8200 | X20: =IF(F20<V20,"considerar","esperar") -> esperar | Y20: =+OXIQUIM!E3/INDICE!F20 -> 0.054666667
B21: 12 | C21: ZOFRI | D21: CONCESIÓN | F21: =+ZOFRI!B3 -> 1004.3 | H21: =+CONCHATORO!C42 -> 0.11030719 | K21: =+ZOFRI!C61 -> 0.040930351 | M21: =+ZOFRI!C57 -> 0.86664405 | O21: =+ZOFRI!C59 -> 0.097503903 | Q21: =+ZOFRI!D3/INDICE!$R$3 -> 946.3 | S21: =IF(F21<Q21,"considerar","esperar") -> esperar | T21: =+ZOFRI!D3/INDICE!F21 -> 0.065957383 | V21: =+ZOFRI!E3/INDICE!$W$3 -> 828.0125 | X21: =IF(F21<V21,"considerar","esperar") -> esperar | Y21: =+ZOFRI!E3/INDICE!F21 -> 0.065957383
B22: 5 | C22: AFPCAPITAL | D22: AFP | F22: =+AFPCAPITAL!B3 -> 272.25 | H22: =+CUPRUM!C45 -> 0.13499339 | K22: =+AFPCAPITAL!C64 -> 0.11298945 | M22: =+AFPCAPITAL!C60 -> 0.80625394 | O22: =+AFPCAPITAL!C62 -> 0.097456151 | Q22: =+CUPRUM!D3/INDICE!$R$3 -> 72.642857 | S22: =IF(F22<Q22,"considerar","esperar") -> esperar | T22: =AFPCAPITAL!D3/INDICE!F22 -> 0.066010407 | V22: =AFPCAPITAL!E3/INDICE!$W$3 -> 291.33333 | X22: =IF(F22<V22,"considerar","esperar") -> considerar | Y22: =AFPCAPITAL!E3/INDICE!F22 -> 0.085607591
B23: 20 | C23: LIPIGAS | D23: GAS | F23: =+LIPIGAS!B3 -> 8145.9 | H23: =+MINERA!C46 -> 0.11849851 | K23: =+LIPIGAS!C61 -> 0.054783521 | M23: =+LIPIGAS!C57 -> 0.77392457 | O23: =+LIPIGAS!C59 -> 0.095437374 | Q23: =+LIPIGAS!D3/INDICE!R3 -> 4357.1429 | S23: =IF(F23<Q23,"considerar","esperar") -> esperar | T23: =+LIPIGAS!D3/INDICE!F24 -> 0.48958233 | V23: =+LIPIGAS!E3/INDICE!W3 -> 3883.3333 | X23: =IF(F23<V23,"considerar","esperar") -> esperar | Y23: =+LIPIGAS!E3/INDICE!F24 -> 0.4986784
B24: 21 | C24: NTGCLGAS | D24: GAS | F24: =+NTGCLGAS!B3 -> 622.98 | H24: =+'AGUAS-A'!C42 -> 0.12387201 | K24: =+NTGCLGAS!C63 -> 0.03147504 | M24: =+NTGCLGAS!C59 -> 0.21375374 | O24: =+NTGCLGAS!C61 -> 0.092860137 | Q24: =+NTGCLGAS!D3/INDICE!$R$3 -> 166.66667 | S24: =IF(F24<Q24,"considerar","esperar") -> esperar | T24: =+NTGCLGAS!D3/INDICE!F25 -> 0.0037921881 | V24: =+NTGCLGAS!E3/INDICE!$W$3 -> 270.83333 | X24: =IF(F24<V24,"considerar","esperar") -> esperar | Y24: =+NTGCLGAS!E3/INDICE!F25 -> 0.007042635
B25: 39 | C25: VOLCAN | D25: INDUSTRIAL | F25: =+VOLCAN!B3 -> 3076.5 | H25: =+'AGUAS-B'!C42 -> 0.12387201 | K25: =+VOLCAN!C55 -> 0.10319443 | M25: =+VOLCAN!C51 -> 0.31356836 | O25: =+VOLCAN!C53 -> 0.085020849 | Q25: =VOLCAN!D3/INDICE!$R$3 -> 2460.9952 | S25: =IF(F25<Q25,"considerar","esperar") -> esperar | T25: =VOLCAN!D3/INDICE!F26 -> 0.51577745 | V25: =VOLCAN!E3/INDICE!$W$3 -> 2157.125 | X25: =IF(F25<V25,"considerar","esperar") -> esperar | Y25: =VOLCAN!E3/INDICE!F26 -> 0.51667665
B26: 11 | C26: SECURITY | D26: BANCO | F26: =+SECURITY!B3 -> 334 | H26: =+SMU!C42 -> 0.12554186 | K26: =+SECURITY!C26 -> 0.058561578 | M26: =+SECURITY!C19 -> 0.614617 | O26: =+SECURITY!C28 -> 0.083499539 | Q26: =SECURITY!D3/INDICE!$R$3 -> 213.09524 | S26: =IF(F26<Q26,"considerar","esperar") -> esperar | T26: =SECURITY!D3/INDICE!F27 -> 0.0097494553 | V26: =SECURITY!D3/INDICE!$W$3 -> 186.45833 | X26: =IF(F26<V26,"considerar","esperar") -> esperar | Y26: =SECURITY!E3/INDICE!F27 -> 0.0097494553
B27: 25 | C27: EMBONOR-B | D27: EMBOTELLADORA | F27: =+'EMBONOR B'!B3 -> 1530 | H27: =+ENTEL!C42 -> 0.13214857 | K27: =+'EMBONOR B'!C61 -> 0.086046794 | M27: =+'EMBONOR B'!C57 -> 0.55905954 | O27: =+'EMBONOR B'!C59 -> 0.077328584 | Q27: =+'EMBONOR B'!D3/INDICE!$R$3 -> 1045.8209 | S27: =IF(F27<Q27,"considerar","esperar") -> esperar | T27: =+'EMBONOR B'!D3/INDICE!F28 -> 0.21097252 | V27: =+'EMBONOR B'!E3/INDICE!$W$3 -> 1191.6667 | X27: =IF(F27<V27,"considerar","esperar") -> esperar | Y27: =+'EMBONOR B'!E3/INDICE!F28 -> 0.27473583 | BC27: XC,,,,,,,,,,,,
B28: 18 | C28: AGUAS-A | D28: AGUAS | F28: =+'AGUAS-A'!B3 -> 347 | H28: =+BCI!C25 -> 0.13334469 | K28: =+'AGUAS-A'!C55 -> 0.031457807 | M28: =+'AGUAS-A'!C51 -> 0.82247372 | O28: =+'AGUAS-A'!C53 -> 0.075918712 | Q28: =+'AGUAS-A'!D3/INDICE!$R$3 -> 128.60005 | S28: =IF(F28<Q28,"considerar","esperar") -> esperar | T28: =+'AGUAS-A'!D3/INDICE!F29 -> 0.060013356 | V28: =+'AGUAS-A'!E3/INDICE!$R$3 -> 212.78576 | X28: =IF(F28<V28,"considerar","esperar") -> esperar | Y28: =+'AGUAS-A'!E3/INDICE!F29 -> 0.099300022
B29: 19 | C29: AGUAS-B | D29: AGUAS | F29: 150 | H29: =+COLBÚN!C44 -> 0.14668408 | K29: =+'AGUAS-B'!C55 -> 0.031456909 | M29: =+'AGUAS-B'!C51 -> 0.8224822 | O29: =+'AGUAS-B'!C53 -> 0.075895141 | Q29: =+'AGUAS-B'!D3/INDICE!$R$3 -> 128.60019 | S29: =IF(F29<Q29,"considerar","esperar") -> esperar | T29: =+'AGUAS-B'!D3/INDICE!F30 -> 0.12732692 | V29: =+'AGUAS-B'!E3/INDICE!$W$3 -> 186.18908 | X29: =IF(F29<V29,"considerar","esperar") -> considerar | Y29: =+'AGUAS-B'!E3/INDICE!F30 -> 0.21068072
B30: 16 | C30: ENELCHILE | D30: ELÉCTRICAS | F30: =+ENELCHILE!B3 -> 70.7 | H30: =+VOLCAN!C42 -> 0.14678967 | K30: =+ENELCHILE!C62 -> 0.10776466 | M30: =+ENELCHILE!C58 -> 1.0397965 | O30: =+ENELCHILE!C60 -> 0.069092385 | Q30: =+ENELCHILE!D3/INDICE!$R$3 -> 42.271429 | S30: =IF(F30<Q30,"considerar","esperar") -> esperar | T30: =+ENELCHILE!D3/INDICE!F31 -> 0.00028183637 | V30: =+ENELCHILE!E3/INDICE!$W$3 -> 36.9875 | X30: =IF(F30<V30,"considerar","esperar") -> esperar | Y30: =+ENELCHILE!E3/INDICE!F31 -> 0.00028183637
B31: 38 | C31: MOLYMET | D31: INDUSTRIAL | F31: =+MOLYMET!B3 -> 10499 | H31: =+SECURITY!C24 -> 0.14923317 | K31: =+MOLYMET!C59 -> 0.053417334 | M31: =+MOLYMET!C55 -> 0.49466284 | O31: =+MOLYMET!C57 -> 0.064150056 | Q31: =MOLYMET!D3/INDICE!$R$3 -> 2059.8524 | S31: =IF(F31<Q31,"considerar","esperar") -> esperar | T31: =MOLYMET!D3/INDICE!F32 -> 0.028580707 | V31: =MOLYMET!E3/INDICE!$W$3 -> 3010.6917 | X31: =IF(F31<V31,"considerar","esperar") -> esperar | Y31: =MOLYMET!E3/INDICE!F32 -> 0.047741394
B32: 26 | C32: CCU | D32: EMBOTELLADORA | F32: =CCU!B3 -> 5045 | H32: =+ILC!C44 -> 0.15240495 | K32: =+CCU!C61 -> 0.039631417 | M32: =+CCU!C57 -> 0.61404159 | O32: =+CCU!C59 -> 0.03470481 | Q32: =+CCU!D3/INDICE!$R$3 -> #REF! | S32: =IF(F32<Q32,"considerar","esperar") -> #REF! | T32: =+CCU!E3/INDICE!F33 -> #REF! | V32: =+CCU!E3/INDICE!$W$3 -> #REF! | X32: =IF(F32<V32,"considerar","esperar") -> #REF! | Y32: =+CCU!E3/INDICE!F33 -> #REF!
B33: 8 | C33: BSANTANDER | D33: BANCO | F33: =+SANTANDER!B3 -> 74.8 | H33: =+TRICAHUE!C42 -> 0.155339 | K33: =+SANTANDER!D39 -> 0.065266442 | M33: =+SANTANDER!D31 -> 0.66713322 | O33: =+SANTANDER!D41 -> 0.060412853 | Q33: =+SANTANDER!E3/INDICE!$R$3 -> 32.79 | S33: =IF(F33<Q33,"considerar","esperar") -> esperar | T33: =+SANTANDER!E3/INDICE!F34 -> 0.0136625 | V33: =+SANTANDER!F3/INDICE!$W$3 -> 28.69125 | X33: =IF(F33<V33,"considerar","esperar") -> esperar | Y33: =+SANTANDER!F3/INDICE!F34 -> 0.0136625
B34: 7 | C34: CHILE | D34: BANCO | F34: =+CHILE!B3 -> 168 | H34: =+ENELCHILE!C42 -> 0.1585192 | K34: =+CHILE!D39 -> 0.086165807 | M34: =+CHILE!D31 -> 0.64984823 | O34: =+CHILE!D41 -> 0.058619969 | Q34: =+CHILE!E3/INDICE!$R$3 -> 104.50078 | S34: =IF(F34<Q34,"considerar","esperar") -> esperar | T34: =+CHILE!E3/INDICE!F35 -> 0.061834778 | V34: =+CHILE!F3/INDICE!$W$3 -> 91.438179 | X34: =IF(F34<V34,"considerar","esperar") -> esperar | Y34: =+CHILE!F3/INDICE!F35 -> 0.061834778
B35: 37 | C35: MANQUEHUE | D35: INMOBILIARIA | F35: =+MANQUEHUE!B3 -> 118.3 | H35: =+'ANDINA A'!C42 -> 0.16433705 | K35: =+MANQUEHUE!C55 -> 0.035795706 | M35: =+MANQUEHUE!C51 -> 0.46550612 | O35: =+MANQUEHUE!C53 -> 0.05362564 | Q35: =MANQUEHUE!D3/INDICE!$R$3 -> 45.238095 | S35: =IF(F35<Q35,"considerar","esperar") -> esperar | T35: =MANQUEHUE!D3/INDICE!F36 -> 5.2341598e-05 | V35: =+MANQUEHUE!E3/INDICE!$W$3 -> 45.791667 | X35: =IF(F35<V35,"considerar","esperar") -> esperar | Y35: =MANQUEHUE!E3/INDICE!F36 -> 6.0550964e-05
B36: 9 | C36: BCI | D36: BANCO | F36: =+BCI!B3 -> 60500 | H36: =+FORUS!C42 -> 0.16607044 | K36: =+BCI!C27 -> 0.090565075 | M36: =+BCI!C19 -> 0.32755118 | O36: =+BCI!C29 -> 0.04800298 | Q36: =+BCI!D3/INDICE!$R$3 -> 15285.714 | S36: =IF(F36<Q36,"considerar","esperar") -> esperar | T36: =+BCI!D3/INDICE!F37 -> 1.2557948 | V36: =+BCI!E3/INDICE!$W$3 -> 13375 | X36: =IF(F36<V36,"considerar","esperar") -> esperar | Y36: =+BCI!E3/INDICE!F37 -> 1.2557948
B37: 27 | C37: CONCHATORO | D37: EMBOTELLADORA | F37: =+CONCHATORO!B3 -> 852.05 | H37: =+EDELMAG!C40 -> 0.1702768 | K37: =+CONCHATORO!C55 -> 0.066166197 | M37: =+CONCHATORO!C51 -> 0.39718171 | O37: =+CONCHATORO!C53 -> 0.039811528 | Q37: =+CONCHATORO!D3/INDICE!$R$3 -> 661.42857 | S37: =IF(F37<Q37,"considerar","esperar") -> esperar | T37: =+CONCHATORO!D3/INDICE!F38 -> 0.12861111 | V37: =+CONCHATORO!E3/INDICE!$W$3 -> 578.75 | X37: =IF(F37<V37,"considerar","esperar") -> esperar | Y37: =+CONCHATORO!E3/INDICE!F38 -> 0.12861111
B38: 40 | C38: FOSFOROS | D38: INDUSTRIAL | F38: =FOSFOROS!B3 -> 360 | H38: =+'EMBONOR A'!C42 -> 0.17189375 | K38: =+FOSFOROS!C55 -> 0.0057335833 | M38: =+FOSFOROS!C51 -> 0.61069473 | O38: =+FOSFOROS!C53 -> 0.020310092 | Q38: =FOSFOROS!D3/INDICE!$R$3 -> 256.54286 | S38: =IF(F38<Q38,"considerar","esperar") -> esperar | T38: =FOSFOROS!D3/INDICE!F39 -> 0.066511111 | V38: =FOSFOROS!E3/INDICE!$W$3 -> 224.475 | X38: =IF(F38<V38,"considerar","esperar") -> esperar | Y38: =FOSFOROS!E3/INDICE!F39 -> 0.066511111
B39: 17 | C39: CGE | D39: ELÉCTRICAS | F39: =CGE!B3 -> 270 | H39: =+'EMBONOR B'!C42 -> 0.17189375 | K39: =+CGE!C61 -> 0.0094653231 | M39: =+CGE!C57 -> 0.30013992 | O39: =+CGE!C59 -> 0.0074732157 | Q39: =+CGE!D3/INDICE!$R$3 -> 39.528571 | S39: =IF(F39<Q39,"considerar","esperar") -> esperar | T39: =+CGE!D3/INDICE!F40 -> 0.00014553966 | V39: =+CGE!E3/INDICE!$W$3 -> 34.5875 | X39: =IF(F39<V39,"considerar","esperar") -> esperar | Y39: =+CGE!E3/INDICE!F40 -> 0.00014553966
B40: 10 | C40: ITAUCL | D40: BANCO | F40: =+ITAU!B3 -> 19012 | H40: =+SANTANDER!D37 -> 0.17232311 | K40: =+ITAU!C26 -> 0.094895127 | M40: =+ITAU!C19 -> 0.061527814 | O40: =+ITAU!C28 -> 8.5686347e-06 | Q40: =ITAU!D3/INDICE!$R$3 -> 1.0441514 | S40: =IF(F40<Q40,"considerar","esperar") -> esperar | T40: =ITAU!D3/INDICE!F41 -> 0.00019133665 | V40: =ITAU!E3/INDICE!$W$3 -> 0.9136325 | X40: =IF(F40<V40,"considerar","esperar") -> esperar | Y40: =ITAU!D3/INDICE!F41 -> 0.00019133665
...

Sheet AAISA
B2: =TODAY()-1 -> 46105 | H2: PROM DIVIDENDOS SIN ADIC/EVENT | I2: PROM DIVIDENDOS TOTALES
B3: {=_FV(B6,"Precio")} -> 382 | H3: =AVERAGE(G49:K49) -> 5.875 | I3: =AVERAGE(G48:K48) -> 5.875
B6: #VALUE! | C6: 2017 | D6: 2018 | E6: 2019 | F6: 2020 | G6: 2021 | H6: 2022 | I6: 2023 | J6: 2024 | K6: 2025 | L6: 2026
B7: Activos corrientes | G7: 105219190000 | H7: 89200440000 | I7: 101399288000 | J7: 132432966000
B8: INVENTARIOS | G8: 0
B9: Acitvos fijos | G9: 200385323000 | H9: 196482993000 | I9: 259862269000 | J9: 362584935000
B10: Encaje | G10: 132001721000 | H10: 124042038000 | I10: 178709698000 | J10: 274487986000
B11: INTANGIBLE | G11: 30790564000 | H11: 31787542000 | I11: 31564610000 | J11: 31638900000 | K11: 34477442000
B12: Activos totales | G12: =+G9+G7 -> 305604513000 | H12: 285683433000 | I12: 361261557000 | J12: =+J9+J7 -> 495017901000
B13: Pasivos corrientes | G13: 40978160000 | H13: 31633208000 | I13: 32025455000 | J13: 37677165000
B14: Pasivos no corrientes | G14: 18392022000 | H14: 14187174000 | I14: 36820323000 | J14: 135225198000
B15: Total Pasivos | G15: =+G14+G13 -> 59370182000 | H15: 45820382000 | I15: =+I13+I14 -> 68845778000 | J15: =+J13+J14 -> 172902363000
B16: Patrimonio | G16: 246234331000 | H16: 239863051000 | I16: =+I12-I15 -> 292415779000 | J16: =+J12-J15 -> 322115538000
B17: Patrimonio Sin Intangible | G17: =+G16-G11 -> 215443767000 | H17: =+H16-H11 -> 208075509000 | I17: =+I16-I11 -> 260851169000 | J17: =+J16-J11 -> 290476638000
B18: Cantidad de acciones | G18: 1000000000 | H18: 1000000000 | I18: 1000000000 | J18: 1000000000
B20: Valor libro | G20: =(G16/G18) -> 246.23433 | H20: =(H16/H18) -> 239.86305 | I20: =(I16/I18) -> 292.41578 | J20: =(J16/J18) -> 322.11554
B21: Valor Libro sin intangible | G21: =+G17/G18 -> 215.44377 | H21: =+H17/H18 -> 208.07551 | I21: =+I17/I18 -> 260.85117 | J21: =+J17/J18 -> 290.47664
B22: Valor sólo con Encaje | G22: =+G10/G18 -> 132.00172 | H22: =+H10/H18 -> 124.04204 | I22: =+I10/I18 -> 178.7097 | J22: =+J10/J18 -> 274.48799
B23: Precio FIN AÑO | H23: 132.1 | I23: 191.26 | J23: 214.94
B24: PER | G24: =+G23/G45 -> 0 | H24: =+H23/H44 -> 6.605 | I24: =+I23/I44 -> 6.1372183 | J24: =+J23/J44 -> 5.7473159
B25: Bolsa/Libro | G25: =+G23/G20 -> 0 | H25: =+H23/H20 -> 0.55073093 | I25: =+I23/I20 -> 0.65406867 | J25: =+J23/J20 -> 0.6672761
B26: GRAHAM | G26: =+G24*G25 -> 0 | H26: =+H24*H25 -> 3.6375778 | I26: =+I24*I25 -> 4.0141622 | J26: =+J24*J25 -> 3.8350466
B27: Bolsa Libro Banda Menor | G27: 0 | H27: 0 | I27: 0 | J27: 0
B28: Bolsa Libro Banda Mayor | G28: 1 | H28: 1 | I28: 1 | J28: 1
B29: Precio Objetivo Menor | G29: =+G27*G20 -> 0 | H29: =+H27*H20 -> 0 | I29: =+I27*I20 -> 0 | J29: =+J27*J20 -> 0
B30: Precio Obejtivo Promedio | G30: =AVERAGE(G29,G31) -> 123.11717 | H30: =AVERAGE(H29,H31) -> 119.93153 | I30: =AVERAGE(I29,I31) -> 146.20789 | J30: =AVERAGE(J29,J31) -> 161.05777
B31: Precio Objetivo Mayor | G31: =+G20*G28 -> 246.23433 | H31: =+H20*H28 -> 239.86305 | I31: =+I20*I28 -> 292.41578 | J31: =+J20*J28 -> 322.11554
B33: Capital de Trabajo | G33: =G7-G13 -> 64241030000 | H33: =H7-H13 -> 57567232000 | I33: =I7-I13 -> 69373833000 | J33: =J7-J13 -> 94755801000
B34: Razón corriente | G34: =G7/G13 -> 2.5676895 | H34: =H7/H13 -> 2.8198354 | I34: =I7/I13 -> 3.1662091 | J34: =J7/J13 -> 3.5149398
B35: Razón ácida | G35: =+(G7-G8)/G13 -> 2.5676895 | H35: =+(H7-H8)/H13 -> 2.8198354 | I35: =+(I7-I8)/I13 -> 3.1662091 | J35: =+(J7-J8)/J13 -> 3.5149398
B36: Razón de endeudamiento | G36: =G15/G12 -> 0.19427129 | H36: =H15/H12 -> 0.16038866 | I36: =I15/I12 -> 0.19057045 | J36: =J15/J12 -> 0.34928507
B39: Ingresos | G39: 10040660000 | H39: 68082093000 | I39: 111180751000 | J39: 148071321000
B40: EBITDA | G40: =+G39-4829551000 -> 5211109000 | H40: 19553316000 | I40: 40368677000 | J40: 50410265000
B41: Margen EBITDA | G41: =G40/G39 -> 0.51900064 | H41: =H40/H39 -> 0.28720204 | I41: =I40/I39 -> 0.36309052 | J41: =J40/J39 -> 0.34044584
B42: Utilidad neta | G42: 3897736000 | H42: 20154682000 | I42: 31163956000 | J42: 37398327000
B43: Margen neto porcentual | G43: =G42/G39 -> 0.3881952 | H43: =H42/H39 -> 0.29603499 | I43: =I42/I39 -> 0.28029992 | J43: =J42/J39 -> 0.25256969
B44: EPS | G44: =4*1000 -> 4000 | H44: 20 | I44: =+I42/I18 -> 31.163956 | J44: =+J42/J18 -> 37.398327
B45: ROE | G45: =G42/G16 -> 0.015829377 | H45: =H42/H16 -> 0.084025789 | I45: =I42/I16 -> 0.10657413 | J45: =J42/J16 -> 0.11610221
B46: ROE AJUSTADO | G46: =+G45/G25 -> #DIV/0! | H46: =+H45/H25 -> 0.1525714 | I46: =+I45/I25 -> 0.16294027 | J46: =+J45/J25 -> 0.17399426
B47: FCF | H47: 14167891000 | I47: 21107849000 | J47: 114613969000
...

Sheet AFPCAPITAL
B2: =TODAY()-1 -> 46105 | D2: PROM DIVIDENDOS SIN ADIC/EVENT | E2: PROM DIVIDENDOS TOTALES
B3: {=_FV(B6,"Precio")} -> 272.25 | D3: =AVERAGE(G48:I48) -> 17.971333 | E3: =AVERAGE(G47:I47) -> 23.306667
B6: #VALUE! | C6: 2017 | D6: 2018 | E6: 2019 | F6: 2020 | G6: 2021 | H6: 2022 | I6: 2023 | J6: 2024 | K6: 2025 | L6: 2026 | M6: 2027 | N6: 2028
B7: Activos corrientes | C7: =+C71 -> 106835735000 | D7: =+D71 -> 74152970000 | E7: =+E71 -> 75692564000 | F7: =+F71 -> 90664627000 | G7: =+G71 -> 63045514000 | H7: =+H71 -> 47079707000 | I7: =+I71 -> 95023798000 | J7: =+J71 -> 122681361000 | ... N7: =+N71 -> 0
B8: INVENTARIOS | C8: 0 | D8: 0 | E8: 0 | F8: 0 | G8: 0 | H8: 0 | I8: 0 | J8: 0 | K8: 0 | L8: 0 | M8: 0 | N8: 0
B9: Acitvos fijos | C9: =+C80 -> 452454294000 | D9: =+D80 -> 457699233000 | E9: =+E80 -> 516817122000 | F9: =+F80 -> 521204053000 | G9: =+G80 -> 494282056000 | H9: =+H80 -> 499374563000 | I9: =+I80 -> 522497691000 | J9: =+J80 -> 555132195000 | ... N9: =+N80 -> 0
B10: Encaje | C10: =+C81 -> 247403057000 | D10: =+D81 -> 254201735000 | E10: =+E81 -> 305961667000 | F10: =+F81 -> 308725396000 | G10: =+G81 -> 284461896000 | H10: =+H81 -> 295637992000 | I10: =+I81 -> 321203585000 | J10: =+J81 -> 346285329000 | ... N10: =+N81 -> 0
B11: INTANGIBLE | C11: =+C84 -> 187962187000 | D11: =+D84 -> 187572055000 | E11: =+E84 -> 187542539000 | F11: =+F84 -> 188298526000 | G11: =+G84 -> 188191450000 | H11: =+H84 -> 188000173000 | I11: =+I84 -> 188488444000 | J11: =+J84 -> 187630376000 | ... N11: =+N84 -> 0
B12: Activos totales | C12: =+C7+C9 -> 559290029000 | D12: =+D7+D9 -> 531852203000 | E12: =+E7+E9 -> 592509686000 | F12: =+F7+F9 -> 611868680000 | G12: =+G7+G9 -> 557327570000 | H12: =+H7+H9 -> 546454270000 | I12: =+I7+I9 -> 617521489000 | J12: =+J7+J9 -> 677813556000 | ... N12: =+N7+N9 -> 0
B13: Pasivos corrientes | C13: =+C93 -> 49180754000 | D13: =+D93 -> 51453291000 | E13: =+E93 -> 62973146000 | F13: =+F93 -> 122980590000 | G13: =+G93 -> 75496876000 | H13: =+H93 -> 55396016000 | I13: =+I93 -> 95915328000 | J13: =+J93 -> 121562114000 | ... N13: =+N93 -> 0
B14: Pasivos no corrientes | C14: =+C102 -> 50100031000 | D14: =+D102 -> 51014275000 | E14: =+E102 -> 69621044000 | F14: =+F102 -> 72124110000 | G14: =+G102 -> 66972919000 | H14: =+H102 -> 64324540000 | I14: =+I102 -> 69239170000 | J14: =+J102 -> 81498345000 | ... N14: =+N102 -> 0
B15: Total Pasivos | C15: =+C14+C13 -> 99280785000 | D15: =+D14+D13 -> 102467566000 | E15: =+E14+E13 -> 132594190000 | F15: =+F14+F13 -> 195104700000 | G15: =+G14+G13 -> 142469795000 | H15: =+H14+H13 -> 119720556000 | I15: =+I14+I13 -> 165154498000 | J15: =+J14+J13 -> 203060459000 | ... N15: =+N14+N13 -> 0
B16: Patrimonio | C16: =+C114 -> 461009244000 | D16: =+D114 -> 429384637000 | E16: =+E114 -> 459915496000 | F16: =+F114 -> 416763980000 | G16: =+G114 -> 414857775000 | H16: =+H114 -> 426733714000 | I16: =+I114 -> 452366991000 | J16: =+J114 -> 474753097000 | ... N16: =+N114 -> 0
B17: Patrimonio Sin Intangible | C17: =+C16-C11 -> 273047057000 | D17: =+D16-D11 -> 241812582000 | E17: =+E16-E11 -> 272372957000 | F17: =+F16-F11 -> 228465454000 | G17: =+G16-G11 -> 226666325000 | H17: =+H16-H11 -> 238733541000 | I17: =+I16-I11 -> 263878547000 | J17: =+J16-J11 -> 287122721000 | ... N17: =+N16-N11 -> 0
B18: Cantidad de acciones | C18: 3123767502 | D18: 3123767502 | E18: 3123767502 | F18: 3123767502 | G18: 3123767502 | H18: 3123767502 | I18: 3123767502 | J18: 3123767502
B20: Valor libro | C20: =(C16/C18) -> 147.58116 | D20: =(D16/D18) -> 137.4573 | E20: =(E16/E18) -> 147.23103 | F20: =(F16/F18) -> 133.41709 | G20: =(G16/G18) -> 132.80687 | H20: =(H16/H18) -> 136.60867 | I20: =(I16/I18) -> 144.81455 | J20: =(J16/J18) -> 151.98093 | ... N20: =(N16/N18) -> #DIV/0!
B21: Valor Libro sin intangible | C21: =+C17/C18 -> 87.409533 | D21: =+D17/D18 -> 77.410557 | E21: =+E17/E18 -> 87.193735 | F21: =+F17/F18 -> 73.137791 | G21: =+G17/G18 -> 72.561842 | H21: =+H17/H18 -> 76.424875 | I21: =+I17/I18 -> 84.474452 | J21: =+J17/J18 -> 91.915522 | ... N21: =+N17/N18 -> #DIV/0!
B22: Valor sólo con Encaje | C22: =+C10/C18 -> 79.200215 | D22: =+D10/D18 -> 81.37665 | E22: =+E10/E18 -> 97.946363 | F22: =+F10/F18 -> 98.831106 | G22: =+G10/G18 -> 91.063722 | H22: =+H10/H18 -> 94.641484 | I22: =+I10/I18 -> 102.8257 | J22: =+J10/J18 -> 110.85503 | ... N22: =+N10/N18 -> #DIV/0!
B23: Precio FIN AÑO | C23: 215.02 | D23: 307.42 | E23: 275.32 | F23: 250.67 | G23: 250.67 | H23: 250.67 | I23: 250.67 | J23: 250.67
B24: PER | C24: =+C23/C43 -> 10.4328 | D24: =+D23/D43 -> 17.069406 | E24: =+E23/E43 -> 9.8787226 | F24: =+F23/F43 -> 13.069343 | G24: =+G23/G43 -> 10.703245 | H24: =+H23/H43 -> 8.8669968 | I24: =+I23/I43 -> 7.3424136 | J24: =+J23/J43 -> 7.5960606 | ... N24: =+N23/N43 -> #DIV/0!
B25: Bolsa Libro | C25: =+C23/C20 -> 1.456961 | D25: =+D23/D20 -> 2.2364764 | E25: =+E23/E20 -> 1.8699863 | F25: =+F23/F20 -> 1.8788447 | G25: =+G23/G20 -> 1.8874777 | H25: =+H23/H20 -> 1.8349495 | I25: =+I23/I20 -> 1.7309725 | J25: =+J23/J20 -> 1.6493516 | ... N25: =+N23/N20 -> #DIV/0!
B26: GRAHAM | C26: =+C24*C25 -> 15.200182 | D26: =+D24*D25 -> 38.175323 | E26: =+E24*E25 -> 18.473076 | F26: =+F24*F25 -> 24.555266 | G26: =+G24*G25 -> 20.202136 | H26: =+H24*H25 -> 16.270491 | I26: =+I24*I25 -> 12.709516 | J26: =+J24*J25 -> 12.528575 | ... N26: =+N24*N25 -> #DIV/0!
B27: Bolsa Libro Banda Menor | C27: 1 | D27: 1 | E27: 2 | F27: 1 | G27: 2 | H27: 2 | I27: 2 | J27: 2
B28: Bolsa Libro Banda Mayor | C28: 2 | D28: 2 | E28: 2.5 | F28: 2 | G28: 2.5 | H28: 2.5 | I28: 2.5 | J28: 2.5
B29: Precio Objetivo Menor | C29: =+C27*C20 -> 147.58116 | D29: =+D27*D20 -> 137.4573 | E29: =+E27*E20 -> 294.46205 | F29: =+F27*F20 -> 133.41709 | G29: =+G27*G20 -> 265.61373 | H29: =+H27*H20 -> 273.21733 | I29: =+I27*I20 -> 289.6291 | J29: =+J27*J20 -> 303.96186 | ... N29: =+N27*N20 -> #DIV/0!
B30: Precio Obejtivo Promedio | C30: =AVERAGE(C29,C31) -> 221.37175 | D30: =AVERAGE(D29,D31) -> 206.18595 | E30: =AVERAGE(E29,E31) -> 331.26981 | F30: =AVERAGE(F29,F31) -> 200.12564 | G30: =AVERAGE(G29,G31) -> 298.81545 | H30: =AVERAGE(H29,H31) -> 307.3695 | I30: =AVERAGE(I29,I31) -> 325.83274 | J30: =AVERAGE(J29,J31) -> 341.9571 | ... N30: =AVERAGE(N29,N31) -> #DIV/0!
B31: Precio Objetivo Mayor | C31: =+C20*C28 -> 295.16233 | D31: =+D20*D28 -> 274.91459 | E31: =+E20*E28 -> 368.07757 | F31: =+F20*F28 -> 266.83419 | G31: =+G20*G28 -> 332.01717 | H31: =+H20*H28 -> 341.52167 | I31: =+I20*I28 -> 362.03638 | J31: =+J20*J28 -> 379.95233 | ... N31: =+N20*N28 -> #DIV/0!
B33: Capital de Trabajo | C33: =C7-C13 -> 57654981000 | D33: =D7-D13 -> 22699679000 | E33: =E7-E13 -> 12719418000 | F33: =F7-F13 -> -32315963000 | G33: =G7-G13 -> -12451362000 | H33: =H7-H13 -> -8316309000 | I33: =I7-I13 -> -891530000 | J33: =J7-J13 -> 1119247000 | ... N33: =N7-N13 -> 0
B34: Razón corriente | C34: =C7/C13 -> 2.1723078 | D34: =D7/D13 -> 1.4411706 | E34: =E7/E13 -> 1.2019816 | F34: =F7/F13 -> 0.73722713 | G34: =G7/G13 -> 0.83507447 | H34: =H7/H13 -> 0.84987532 | I34: =I7/I13 -> 0.99070503 | J34: =J7/J13 -> 1.0092072 | ... N34: =N7/N13 -> #DIV/0!
B35: Razón ácida | C35: =+(C7-C8)/C13 -> 2.1723078 | D35: =+(D7-D8)/D13 -> 1.4411706 | E35: =+(E7-E8)/E13 -> 1.2019816 | F35: =+(F7-F8)/F13 -> 0.73722713 | G35: =+(G7-G8)/G13 -> 0.83507447 | H35: =+(H7-H8)/H13 -> 0.84987532 | I35: =+(I7-I8)/I13 -> 0.99070503 | J35: =+(J7-J8)/J13 -> 1.0092072 | ... N35: =+(N7-N8)/N13 -> #DIV/0!
B36: Razón de endeudamiento | C36: =C15/C12 -> 0.17751217 | D36: =D15/D12 -> 0.19266173 | E36: =E15/E12 -> 0.223784 | F36: =F15/F12 -> 0.31886695 | G36: =G15/G12 -> 0.25563027 | H36: =H15/H12 -> 0.21908614 | I36: =I15/I12 -> 0.26744737 | J36: =J15/J12 -> 0.29958158 | ... N36: =N15/N12 -> #DIV/0!
B38: Ingresos | C38: =+C118+C119 -> 153081797000 | D38: =+D118+D119 -> 143493133000 | E38: =+E118+E119 -> 189509366000 | F38: =+F118+F119 -> 167313902000 | G38: =+G118+G119 -> 175110953000 | H38: =+H118+H119 -> 191817950000 | I38: =+I118+I119 -> 221149543000 | J38: =+J118+J119 -> 232088060000 | ... N38: =+N118+N119 -> 0
B39: EBITDA | C39: =+C118+C119+C120+C123 -> 80444186000 | D39: =+D118+D119+D120+D123 -> 69089992000 | E39: =+E118+E119+E120+E123 -> 113115060000 | F39: =+F118+F119+F120+F123 -> 85367914000 | G39: =+G118+G119+G120+G123 -> 94674230000 | H39: =+H118+H119+H120+H123 -> 108835835000 | I39: =+I118+I119+I120+I123 -> 135181649000 | J39: =+J118+J119+J120+J123 -> 137691293000 | ... N39: =+N118+N119+N120+N123 -> 0
B40: Margen EBITDA | C40: =C39/C38 -> 0.52549805 | D40: =D39/D38 -> 0.4814864 | E40: =E39/E38 -> 0.59688374 | F40: =F39/F38 -> 0.51022607 | G40: =G39/G38 -> 0.54065282 | H40: =H39/H38 -> 0.56739129 | I40: =I39/I38 -> 0.61126805 | J40: =J39/J38 -> 0.59327177 | ... N40: =N39/N38 -> #DIV/0!
B41: Utilidad neta | C41: =+C134 -> 64365815000 | D41: =+D134 -> 56257053000 | E41: =+E134 -> 87047237000 | F41: =+F134 -> 59912751000 | G41: =+G134 -> 73164253000 | H41: =+H134 -> 88294898000 | I41: =+I134 -> 106632475000 | J41: =+J134 -> 102713160000 | ... N41: =+N134 -> 0
B42: Margen neto porcentual | C42: =C41/C38 -> 0.42046681 | D42: =D41/D38 -> 0.39205397 | E42: =E41/E38 -> 0.45932947 | F42: =F41/F38 -> 0.35808591 | G42: =G41/G38 -> 0.41781654 | H42: =H41/H38 -> 0.46030571 | I42: =I41/I38 -> 0.48217362 | J42: =J41/J38 -> 0.44256116 | ... N42: =N41/N38 -> #DIV/0!
B43: EPS | C43: =+C135 -> 20.61 | D43: =+D135 -> 18.01 | E43: =+E135 -> 27.87 | F43: =+F135 -> 19.18 | G43: =+G135 -> 23.42 | H43: =+H135 -> 28.27 | I43: =+I135 -> 34.14 | J43: =+J135 -> 33 | ... N43: =+N135 -> 0
B44: ROE | C44: =C41/C16 -> 0.13961936 | D44: =D41/D16 -> 0.13101785 | E44: =E41/E16 -> 0.18926789 | F44: =F41/F16 -> 0.14375703 | G44: =G41/G16 -> 0.17635985 | H44: =H41/H16 -> 0.20690865 | I44: =I41/I16 -> 0.23572117 | J44: =J41/J16 -> 0.21635069 | ... N44: =N41/N16 -> #DIV/0!
B45: ROE PROMEDIO 3 AÑOS | C45: =AVERAGE(G44:I44) -> 0.20632989
B46: FCF | C46: =+C148 -> 76354133000 | D46: =+D148 -> 42451140000 | E46: =+E148 -> 44868907000 | F46: =+F148 -> 112938995000 | G46: =+G148 -> -12149934000 | H46: =+H148 -> 68391131000 | I46: =+I148 -> 90202808000 | J46: =+J148 -> 83687787000 | ... N46: =+N148 -> 0
...

Sheet AGUAS-A
B2: =TODAY()-1 -> 46105 | D2: PROM DIVIDENDOS SIN ADIC/EVENT | E2: PROM DIVIDENDOS TOTALES
B3: {=_FV(B6,"Precio")} -> 347 | D3: =AVERAGE(G45:I45) -> 9.0020033 | E3: =AVERAGE(G44:I44) -> 14.895003
B6: #VALUE! | C6: 2017 | D6: 2018 | E6: 2019 | F6: 2020 | G6: 2021 | H6: 2022 | I6: 2023 | J6: 2024 | K6: 2025 | L6: 2026 | M6: 2027 | N6: 2028
B7: Activos corrientes | C7: =+C61 -> 150618761000 | D7: =+D61 -> 168513972000 | E7: =+E61 -> 197676646000 | F7: =+F61 -> 302254499000 | G7: =+G61 -> 283854689000 | H7: =+H61 -> 324838124000 | I7: =+I61 -> 275000996000 | J7: =+J61 -> 0 | ... N7: =+N61 -> 0
B8: Cuentas por cobrar | C8: =+C65 -> 113515790000 | D8: =+D65 -> 116821062000 | E8: =+E65 -> 115937498000 | F8: =+F65 -> 87482681000 | G8: =+G65 -> 101105786000 | H8: =+H65 -> 122777327000 | I8: =+I65 -> 132007468000 | J8: =+J65 -> 0 | ... N8: =+N65 -> 0
B9: Inventario | C9: =+C67 -> 3925378000 | D9: =+D67 -> 3636388000 | E9: =+E67 -> 3810599000 | F9: =+F67 -> 3954953000 | G9: =+G67 -> 5185858000 | H9: =+H67 -> 12790532000 | I9: =+I67 -> 12812483000 | J9: =+J67 -> 0 | ... N9: =+N67 -> 0
B10: Acitvos no corrientes (no circulantes o fijos) | C10: =+C70 -> 1646261375000 | D10: =+D70 -> 1737538127000 | E10: =+E70 -> 1803767656000 | F10: =+F70 -> 1842181989000 | G10: =+G70 -> 1945366921000 | H10: =+H70 -> 2054511436000 | I10: =+I70 -> 2148343319000 | J10: =+J70 -> 0 | ... N10: =+N70 -> 0
B11: Activos totales | C11: =+C10+C7 -> 1796880136000 | D11: =+D10+D7 -> 1906052099000 | E11: =+E10+E7 -> 2001444302000 | F11: =+F10+F7 -> 2144436488000 | G11: =+G10+G7 -> 2229221610000 | H11: =+H10+H7 -> 2379349560000 | I11: =+I10+I7 -> 2423344315000 | J11: =+J10+J7 -> 0 | ... N11: =+N10+N7 -> 0
B12: Pasivos corrientes | C12: =+C84 -> 237111903000 | D12: =+D84 -> 242318524000 | E12: =+E84 -> 242137717000 | F12: =+F84 -> 244032589000 | G12: =+G84 -> 248642211000 | H12: =+H84 -> 265797147000 | I12: =+I84 -> 361668126000 | J12: =+J84 -> 0 | ... N12: =+N84 -> 0
B13: Pasivos no corrientes | C13: =+C94 -> 866468756000 | D13: =+D94 -> 976742178000 | E13: =+E94 -> 1071833122000 | F13: =+F94 -> 1059655092000 | G13: =+G94 -> 1138031686000 | H13: =+H94 -> 1274661314000 | I13: =+I94 -> 1175540305000 | J13: =+J94 -> 0 | ... N13: =+N94 -> 0
B14: Total Pasivos | C14: =+C12+C13 -> 1103580659000 | D14: =+D12+D13 -> 1219060702000 | E14: =+E12+E13 -> 1313970839000 | F14: =+F12+F13 -> 1303687681000 | G14: =+G12+G13 -> 1386673897000 | H14: =+H12+H13 -> 1540458461000 | I14: =+I12+I13 -> 1537208431000 | J14: =+J12+J13 -> 0 | ... N14: =+N12+N13 -> 0
B15: Patrimonio | C15: =+C109 -> 642630776000 | D15: =+D109 -> 638620196000 | E15: =+E109 -> 644453334000 | F15: =+F109 -> 840723242000 | G15: =+G109 -> 842520215000 | H15: =+H109 -> 838861526000 | I15: =+I109 -> 886107830000 | J15: =+J109 -> 0 | ... N15: =+N109 -> 0
B16: Cantidad de acciones | C16: 6118965160 | D16: 6118965160 | E16: 6118965160 | F16: 6118965160 | G16: 6118965160 | H16: 6118965160 | I16: 6118965160
B18: Valor libro | C18: =(C15/C16) -> 105.02279 | D18: =(D15/D16) -> 104.36735 | E18: =(E15/E16) -> 105.32064 | F18: =(F15/F16) -> 137.39631 | G18: =(G15/G16) -> 137.68998 | H18: =(H15/H16) -> 137.09206 | I18: =(I15/I16) -> 144.81335 | J18: =(J15/J16) -> #DIV/0! | ... N18: =(N15/N16) -> #DIV/0!
B19: Precio FIN AÑO | C19: 407.5 | D19: 382 | E19: 319 | F19: 229 | G19: 155 | H19: 196 | I19: 284.6
B20: PER | C20: =+C19/C40 -> 17.858708 | D20: =+D19/D40 -> 17.180121 | E20: =+E19/E40 -> 13.771369 | F20: =+F19/F40 -> 14.198028 | G20: =+G19/G40 -> 9.4236381 | H20: =+H19/H40 -> 14.068332 | I20: =+I19/I40 -> 13.055046 | J20: =+J19/J40 -> #DIV/0! | ... N20: =+N19/N40 -> #DIV/0!
B21: Bolsa/Libro | C21: =+C19/C18 -> 3.8801103 | D21: =+D19/D18 -> 3.6601484 | E21: =+E19/E18 -> 3.028846 | F21: =+F19/F18 -> 1.6667114 | G21: =+G19/G18 -> 1.1257173 | H21: =+H19/H18 -> 1.4296962 | I21: =+I19/I18 -> 1.9652885 | J21: =+J19/J18 -> #DIV/0! | ... N21: =+N19/N18 -> #DIV/0!
B22: GRAHAM | C22: =+C20*C21 -> 69.293757 | D22: =+D20*D21 -> 62.881794 | E22: =+E20*E21 -> 41.711357 | F22: =+F20*F21 -> 23.664016 | G22: =+G20*G21 -> 10.608353 | H22: =+H20*H21 -> 20.113441 | I22: =+I20*I21 -> 25.656931 | J22: =+J20*J21 -> #DIV/0! | ... N22: =+N20*N21 -> #DIV/0!
B23: Bolsa Libro Banda Menor | C23: =IF(C41<10%,0,IF(15%<C41,2,1)) -> 2 | D23: =IF(D41<10%,0,IF(15%<D41,2,1)) -> 2 | E23: =IF(E41<10%,0,IF(15%<E41,2,1)) -> 2 | F23: =IF(F41<10%,0,IF(15%<F41,2,1)) -> 1 | G23: =IF(G41<10%,0,IF(15%<G41,2,1)) -> 1 | H23: =IF(H41<10%,0,IF(15%<H41,2,1)) -> 1 | I23: =IF(I41<10%,0,IF(15%<I41,2,1)) -> 2 | J23: =IF(J41<10%,0,IF(15%<J41,2,1)) -> #DIV/0! | ... N23: =IF(N41<10%,0,IF(15%<N41,2,1)) -> #DIV/0!
B24: Bolsa Libro Banda Mayor | C24: =IF(C41<10%,1,IF(15%<C41,2.5,2)) -> 2.5 | D24: =IF(D41<10%,1,IF(15%<D41,2.5,2)) -> 2.5 | E24: =IF(E41<10%,1,IF(15%<E41,2.5,2)) -> 2.5 | F24: =IF(F41<10%,1,IF(15%<F41,2.5,2)) -> 2 | G24: =IF(G41<10%,1,IF(15%<G41,2.5,2)) -> 2 | H24: =IF(H41<10%,1,IF(15%<H41,2.5,2)) -> 2 | I24: =IF(I41<10%,1,IF(15%<I41,2.5,2)) -> 2.5 | J24: =IF(J41<10%,1,IF(15%<J41,2.5,2)) -> #DIV/0! | ... N24: =IF(N41<10%,1,IF(15%<N41,2.5,2)) -> #DIV/0!
B25: Precio Objetivo Menor | C25: =+C23*C18 -> 210.04557 | D25: =+D23*D18 -> 208.73471 | E25: =+E23*E18 -> 210.64128 | F25: =+F23*F18 -> 137.39631 | G25: =+G23*G18 -> 137.68998 | H25: =+H23*H18 -> 137.09206 | I25: =+I23*I18 -> 289.6267 | J25: =+J23*J18 -> #DIV/0! | ... N25: =+N23*N18 -> #DIV/0!
B26: Precio Obejtivo Promedio | C26: =AVERAGE(C25,C27) -> 236.30127 | D26: =AVERAGE(D25,D27) -> 234.82654 | E26: =AVERAGE(E25,E27) -> 236.97144 | F26: =AVERAGE(F25,F27) -> 206.09447 | G26: =AVERAGE(G25,G27) -> 206.53498 | H26: =AVERAGE(H25,H27) -> 205.63809 | I26: =AVERAGE(I25,I27) -> 325.83003 | J26: =AVERAGE(J25,J27) -> #DIV/0! | ... N26: =AVERAGE(N25,N27) -> #DIV/0!
B27: Precio Objetivo Mayor | C27: =+C18*C24 -> 262.55697 | D27: =+D18*D24 -> 260.91838 | E27: =+E18*E24 -> 263.3016 | F27: =+F18*F24 -> 274.79262 | G27: =+G18*G24 -> 275.37997 | H27: =+H18*H24 -> 274.18412 | I27: =+I18*I24 -> 362.03337 | J27: =+J18*J24 -> #DIV/0! | ... N27: =+N18*N24 -> #DIV/0!
B29: Capital de Trabajo | C29: =C7-C12 -> -86493142000 | D29: =D7-D12 -> -73804552000 | E29: =E7-E12 -> -44461071000 | F29: =F7-F12 -> 58221910000 | G29: =G7-G12 -> 35212478000 | H29: =H7-H12 -> 59040977000 | I29: =I7-I12 -> -86667130000 | J29: =J7-J12 -> 0 | ... N29: =N7-N12 -> 0
B30: Razón corriente | C30: =C7/C12 -> 0.63522227 | D30: =D7/D12 -> 0.6954234 | E30: =E7/E12 -> 0.81638106 | F30: =F7/F12 -> 1.2385825 | G30: =G7/G12 -> 1.1416191 | H30: =H7/H12 -> 1.222128 | I30: =I7/I12 -> 0.76036835 | J30: =J7/J12 -> #DIV/0! | ... N30: =N7/N12 -> #DIV/0!
B31: Razón ácida | C31: =+(C7-C9)/C12 -> 0.61866731 | D31: =+(D7-D9)/D12 -> 0.68041676 | E31: =+(E7-E9)/E12 -> 0.80064374 | F31: =+(F7-F9)/F12 -> 1.2223759 | G31: =+(G7-G9)/G12 -> 1.1207624 | H31: =+(H7-H9)/H12 -> 1.1740066 | I31: =+(I7-I9)/I12 -> 0.72494227 | J31: =+(J7-J9)/J12 -> #DIV/0! | ... N31: =+(N7-N9)/N12 -> #DIV/0!
B32: Razón de endeudamiento | C32: =C14/C11 -> 0.61416487 | D32: =D14/D11 -> 0.63957365 | E32: =E14/E11 -> 0.65651132 | F32: =F14/F11 -> 0.60793952 | G32: =G14/G11 -> 0.62204399 | H32: =H14/H11 -> 0.64742839 | I32: =I14/I11 -> 0.63433348 | J32: =J14/J11 -> #DIV/0! | ... N32: =N14/N11 -> #DIV/0!
B35: Ingresos | C35: =+C114 -> 509540577000 | D35: =+D114 -> 530404680000 | E35: =+E114 -> 484329084000 | F35: =+F114 -> 478773563000 | G35: =+G114 -> 506459633000 | H35: =+H114 -> 575465445000 | I35: =+I114 -> 640855854000 | J35: =+J114 -> 0 | ... N35: =+N114 -> 0
B36: EBIT | C36: =+C122 -> 226819054000 | D36: =+D122 -> 233071676000 | E36: =+E122 -> 235636236000 | F36: =+F122 -> 162824880000 | G36: =+G122 -> 212947803000 | H36: =+H122 -> 228258340000 | I36: =+I122 -> 256251484000 | J36: =+J122 -> 0 | ... N36: =+N122 -> 0
B37: Margen EBIT | C37: =C36/C35 -> 0.44514424 | D37: =D36/D35 -> 0.43942236 | E37: =E36/E35 -> 0.48652093 | F37: =F36/F35 -> 0.34008745 | G37: =G36/G35 -> 0.42046353 | H37: =H36/H35 -> 0.39664995 | I37: =I36/I35 -> 0.39985822 | J37: =J36/J35 -> #DIV/0! | ... N37: =N36/N35 -> #DIV/0!
B38: Utilidad neta | C38: =+C133 -> 139620280000 | D38: =+D133 -> 136056517000 | E38: =+E133 -> 141737188000 | F38: =+F133 -> 98691668000 | G38: =+G133 -> 100644529000 | H38: =+H133 -> 85248734000 | I38: =+I133 -> 133390421000 | J38: =+J133 -> 0 | ... N38: =+N133 -> 0
B39: Margen neto porcentual | C39: =C38/C35 -> 0.27401209 | D39: =D38/D35 -> 0.25651455 | E39: =E38/E35 -> 0.29264645 | F39: =F38/F35 -> 0.20613433 | G39: =G38/G35 -> 0.19872172 | H39: =H38/H35 -> 0.14813875 | I39: =I38/I35 -> 0.20814419 | J39: =J38/J35 -> #DIV/0! | ... N39: =N38/N35 -> #DIV/0!
B40: EPS | C40: =+C134 -> 22.818 | D40: =+D134 -> 22.235 | E40: =+E134 -> 23.164 | F40: =+F134 -> 16.129 | G40: =+G134 -> 16.448 | H40: =+H134 -> 13.932 | I40: =+I134 -> 21.8 | J40: =+J134 -> 0 | ... N40: =+N134 -> 0
B41: ROE | C41: =C38/C15 -> 0.21726361 | D41: =D38/D15 -> 0.21304763 | E41: =E38/E15 -> 0.21993398 | F41: =F38/F15 -> 0.11738901 | G41: =G38/G15 -> 0.11945652 | H41: =H38/H15 -> 0.10162432 | I41: =I38/I15 -> 0.1505352 | J41: =J38/J15 -> #DIV/0! | ... N41: =N38/N15 -> #DIV/0!
B42: ROE PROMEDIO | C42: =AVERAGE(G41:I41) -> 0.12387201
B43: FCF | C43: =+C146 -> 101170091000 | D43: =+D146 -> 108261532000 | E43: =+E146 -> 94891034000 | F43: =+F146 -> 36288731000 | G43: =+G146 -> 69607469000 | H43: =+H146 -> 81536376000 | I43: =+I146 -> 79751783000 | J43: =+J146 -> 0 | ... N43: =+N146 -> 0
B44: Dividendos | C44: =SUM(C46:C49) -> 22.118 | D44: =SUM(D46:D49) -> 22.49966 | E44: =SUM(E46:E49) -> 21.7114 | F44: =SUM(F46:F49) -> 17.852 | G44: =SUM(G46:G49) -> 17.189 | H44: =SUM(H46:H49) -> 12.747 | I44: =SUM(I46:I49) -> 14.74901 | J44: =SUM(J46:J49) -> 0 | ... N44: =SUM(N46:N49) -> 0
B45: Dividendos sin Adic/Event | C45: =+C46+C47 -> 6.861 | D45: =+D46+D47 -> 22.49966 | E45: =+E46+E47 -> 21.7114 | F45: =+F46+F47 -> 17.852 | G45: =+G46+G47 -> 6.537 | H45: =+H46+H47 -> 5.72 | I45: =+I46+I47 -> 14.74901 | J45: =+J46+J47 -> 0 | ... N45: =+N46+N47 -> 0
B46: Definitivo | D46: 15.63866 | E46: 14.6474 | I46: 8.21196
B47: Provisorio | C47: 6.861 | D47: 6.861 | E47: 7.064 | F47: =10.59+7.262 -> 17.852 | G47: 6.537 | H47: 5.72 | I47: 6.53705
...

Sheet AGUAS-B
B2: =TODAY()-1 -> 46105 | D2: PROM DIVIDENDOS SIN ADIC/EVENT | E2: PROM DIVIDENDOS TOTALES
